Workbook

Sheet Portada
A1: CASOS DE PRUEBA QA — Integration Hub · Money-path MT101
A2: Fecha | B2: 2026-07-16
A3: Version | B3: 1.0
A4: Total | B4: 236 casos en 9 fases (F0..F8) · 111 Manual-QA / 93 Tecnico-Dev / 32 Automatizado-IT
A6: QUE ES ESTO
A7: Proposito | B7: Suite para que el Equipo de QA valide el money-path MT101 (banco-a-banco) de punta a punta: desde la configuracion del catalogo hasta la ejecucion y los reprocesos, verificando SIEMPRE por las vistas de la UI (no por API).
A9: INDICE DE PESTANAS
A10: 1. Portada | B10: Esta hoja: arranque rapido, indice y leyenda.
A11: 2. Casos | B11: Los 236 casos ORDENADOS por ejecucion (columnas Orden y Fase).
A12: 3. Preparacion | B12: Acceso, usuarios, navegacion y orden de ejecucion. LEER PRIMERO.
A13: 4. Datos-Formularios | B13: Valores exactos por campo del CRUD (Fuentes/Conexiones/Readers/Procesos).
A14: 5. Flujo-E2E | B14: Guion E2E + archivos de datos (10k) + como verificar por la UI.
A15: 6. Resumen | B15: Conteos por Estado/Ejecutor/Fase/Modulo (formulas).
A16: 7. Aprobacion | B16: Checklist de gates de homologacion + firmas.
A18: ARRANQUE RAPIDO
A19: 1) Stack arriba | B19: Local: docker compose -f docker-compose.int.yml up -d (en ops/fase-7-deploy/dist/onprem). Primera vez: cargar imagenes con docker load (ver LEEME-DEPLOY).
A20: 2) Acceso | B20: Abrir https://<host>/appih (local: https://192.168.0.15:8443/appih). Aceptar el cert self-signed (ver Preparacion).
A21: 3) Login | B21: Usuarios de prueba en la hoja Preparacion (admin/admin123, etc.). El QA NO comparte credenciales.
A22: 4) Datos | B22: Archivos de 10k en qa/fase-6-qa/datos-prueba/ (mt101-10k.csv). El QA no genera nada.
A23: 5) Ejecutar | B23: Seguir el orden de Fase (F0 Infra -> ... -> F8 Aceptacion). Marcar la columna Estado en la hoja Casos.
A24: 6) Cierre | B24: Al terminar, llenar la hoja Aprobacion (gates + firmas).
A26: LEYENDA
A27: Ejecutor | B27: Manual-QA (verde)=QA en la UI ; Tecnico/Dev (amarillo)=apoyo dev ; Automatizado-IT (azul)=ya cubierto por prueba automatica.
A28: Estado | B28: Columna Estado en Casos: Pendiente / Pass / Fail / Blocked / N/A (desplegable). El Resumen cuenta solo.
A29: Verificar | B29: SIEMPRE por vistas de la UI. Hub: Ejecuciones > pestana Tareas (Procesados/Escritos). Nunca por API.

Sheet Casos
A1: Orden | B1: Fase | C1: ID | D1: Modulo | E1: Ejecutor | F1: Escenario | G1: Precondicion | H1: Pasos | I1: Resultado esperado | J1: Prioridad | K1: Tipo | L1: Estado | M1: Tester | N1: Fecha | O1: Observaciones | P1: Ejecucion v2 | Q1: Resultado v2 | R1: Coincide v1-v2
A2: 1 | B2: F0. Infra / Deploy / Acceso | C2: INFRA-01 | D2: INFRA | E2: Manual-QA | F2: Acceso por dominio | G2: DNS/hosts resuelve el dominio; stack arriba | H2: 1) Abrir https://<dominio>/appih en el navegador 2) Aceptar el aviso de cert self-signed (ver Preparacion) | I2: Carga la UI de Integration Hub | J2: Alta | K2: Funcional | L2: Pass | O2: UI /appih carga HTTP 200 (13) | P2: Si | Q2: Pass | R2: Si
A3: 2 | B3: F0. Infra / Deploy / Acceso | C3: INFRA-02 | D3: INFRA | E3: Manual-QA | F3: Acceso por IP-LAN | G3: Stack arriba; en la PC cliente el hosts apunta el dominio a la IP | H3: 1) Abrir la URL con el dominio (mapeado a la IP) 2) Aceptar cert | I3: Carga la UI; el login funciona | J3: Alta | K3: Funcional | L3: Blocked | O3: acceso por IP-LAN desde otra PC (hosts) | P3: Si | Q3: Pass | R3: NO
A4: 3 | B4: F0. Infra / Deploy / Acceso | C4: INFRA-03 | D4: INFRA | E4: Tecnico/Dev | F4: Acceso por IP publica (internet) | G4: Router con port-forward 443 + DNS publico | H4: 1) Desde internet, abrir https://<dominio>/appih | I4: Carga la UI | J4: Media | K4: Funcional | L4: Blocked | O4: internet + port-forward 443 | P4: Si | Q4: Blocked | R4: Si
A5: 4 | B5: F0. Infra / Deploy / Acceso | C5: INFRA-04 | D5: INFRA | E5: Tecnico/Dev | F5: http a puerto https | G5: Stack arriba | H5: 1) Abrir http://<host>:443/ (http, no https) | I5: HTTP 400 'plain HTTP request was sent to HTTPS port' | J5: Baja | K5: Negativo | L5: Pass | O5: http a puerto https -> 400 (04) | P5: Si | Q5: Pass | R5: Si
A6: 5 | B6: F0. Infra / Deploy / Acceso | C6: INFRA-05 | D6: INFRA | E6: Manual-QA | F6: Cert self-signed | G6: Stack con cert self-signed | H6: 1) Abrir la URL https | I6: Sale el aviso de seguridad; al aceptar la excepcion (o importar el cert) se puede continuar | J6: Media | K6: Seguridad | L6: Pass | O6: cert self-signed dual, 5 SAN (12) | P6: No | R6: -
A7: 6 | B7: F0. Infra / Deploy / Acceso | C7: INFRA-06 | D7: INFRA | E7: Tecnico/Dev | F7: Subpath /appih | G7: Imagen native-appih | H7: 1) Con curl: GET /appih/ 2) Revisar el HTML | I7: El index trae base href /appih/ y los recursos cargan bajo /appih | J7: Alta | K7: Funcional | L7: Pass | O7: base href=/appih/ (06) | P7: Si | Q7: Pass | R7: Si
A8: 7 | B8: F0. Infra / Deploy / Acceso | C8: INFRA-07 | D8: INFRA | E8: Manual-QA | F8: La raiz redirige a /appih | G8: Stack arriba | H8: 1) Abrir la URL sin /appih (solo el host) | I8: Redirige automaticamente a /appih/ | J8: Baja | K8: Funcional | L8: Pass | O8: GET / -> 302 /appih/ (05) | P8: Si | Q8: Pass | R8: Si
A9: 8 | B9: F0. Infra / Deploy / Acceso | C9: INFRA-08 | D9: INFRA | E9: Tecnico/Dev | F9: Health/readiness | G9: Stack arriba | H9: 1) GET /q/health/ready (curl o navegador) | I9: Devuelve status UP con los chequeos de DB (y mensajeria) en UP | J9: Alta | K9: Funcional | L9: Pass | O9: health/ready UP: DB+JMS+messaging (02) | P9: Si | Q9: Pass | R9: Si
A10: 9 | B10: F0. Infra / Deploy / Acceso | C10: INFRA-09 | D10: INFRA | E10: Tecnico/Dev | F10: Ruteo de nginx | G10: Stack arriba | H10: 1) Probar /appih/ (app), /api/ (API), /iam/ (login), /pluginwidget/ (widget) | I10: Cada ruta responde desde su servicio correcto | J10: Alta | K10: Funcional | L10: Pass | O10: nginx: /appih,/iam,/pluginwidget 200; /api 401 (03) | P10: Si | Q10: Pass | R10: Si
A11: 10 | B11: F0. Infra / Deploy / Acceso | C11: INFRA-10 | D11: INFRA | E11: Tecnico/Dev | F11: Keycloak honra https tras el proxy | G11: Stack arriba | H11: 1) GET /iam/realms/integration-hub/.well-known/openid-configuration | I11: Las URLs (auth/token/issuer) son https con el hostname publico | J11: Alta | K11: Funcional | L11: Pass | O11: issuer/auth/token https 192.168.0.15/iam (11) | P11: Si | Q11: Pass | R11: Si
A12: 11 | B12: F0. Infra / Deploy / Acceso | C12: INFRA-11 | D12: INFRA | E12: Tecnico/Dev | F12: Branding del login (nativo) | G12: Imagen nativa | H12: 1) GET /appih/api/branding | I12: HTTP 200 (no 500) -> el logo/marca del login carga bien | J12: Media | K12: Funcional | L12: Pass | O12: /appih/api/branding 200 (07) | P12: Si | Q12: Pass | R12: Si
A13: 12 | B13: F0. Infra / Deploy / Acceso | C13: INFRA-12 | D13: INFRA | E13: Tecnico/Dev | F13: Arranque del stack | G13: Imagenes cargadas (docker load) | H13: 1) docker compose up -d 2) docker compose ps | I13: Todos los contenedores en Up; postgres y keycloak en healthy | J13: Alta | K13: Funcional | L13: Pass | O13: 15 contenedores nativos Up, datastores healthy (13) | P13: Si | Q13: Pass | R13: Si
A14: 13 | B14: F0. Infra / Deploy / Acceso | C14: INFRA-13 | D14: INFRA | E14: Tecnico/Dev | F14: Persistencia tras reinicio | G14: Stack con datos | H14: 1) docker compose restart 2) Verificar que los datos sigan | I14: Los datos operacionales persisten y la app recupera | J14: Media | K14: Funcional | L14: Blocked | O14: reinicio del stack (no ejecutado para preservar evidencia) | P14: Si | Q14: Blocked | R14: Si
A15: 14 | B15: F0. Infra / Deploy / Acceso | C15: INFRA-14 | D15: INFRA | E15: Tecnico/Dev | F15: Puerto ocupado | G15: Otro servicio usando el 443/8443 | H15: 1) Levantar el stack | I15: nginx no puede bindear; el error es claro; se resuelve liberando el puerto o cambiando NGINX_PORTS | J15: Baja | K15: Negativo | L15: Blocked | O15: ocupar el puerto (disruptivo) | P15: Si | Q15: Blocked | R15: Si
A16: 15 | B16: F1. Autenticacion / Roles | C16: AUTH-01 | D16: AUTH | E16: Manual-QA | F16: Login exitoso | G16: Usuario valido (ver Preparacion); stack arriba | H16: 1) Abrir la URL /appih 2) Te redirige a la pantalla de login (Keycloak) 3) Ingresar usuario y contrasena 4) Aceptar | I16: Vuelves autenticado a la app; se ve tu nombre de usuario arriba | J16: Alta | K16: Funcional | L16: Blocked | O16: login Keycloak: lo hace el usuario (regla) / UI | P16: No | R16: -
A17: 16 | B17: F1. Autenticacion / Roles | C17: AUTH-02 | D17: AUTH | E17: Manual-QA | F17: Login con credenciales invalidas | G17: Stack arriba | H17: 1) En el login, ingresar una contrasena incorrecta 2) Aceptar | I17: Keycloak muestra 'credenciales invalidas'; no entras | J17: Alta | K17: Negativo | L17: Blocked | O17: login UI | P17: No | R17: -
A18: 17 | B18: F1. Autenticacion / Roles | C18: AUTH-03 | D18: AUTH | E18: Manual-QA | F18: Logout | G18: Sesion iniciada (P) | H18: 1) Click en el menu de usuario > Salir | I18: Se cierra la sesion; vuelve a la pantalla de login | J18: Media | K18: Funcional | L18: Blocked | O18: logout UI | P18: No | R18: -
A19: 18 | B19: F1. Autenticacion / Roles | C19: AUTH-04 | D19: AUTH | E19: Tecnico/Dev | F19: PKCE obligatorio (S256) | G19: - | H19: 1) Con dev, llamar al endpoint de auth SIN el parametro code_challenge | I19: Keycloak rechaza: error 'Missing parameter: code_challenge_method' (el login normal del navegador SI lo manda) | J19: Alta | K19: Seguridad | L19: Pass | O19: PKCE: Missing parameter code_challenge_method (09) | P19: Si | Q19: Pass | R19: Si
A20: 19 | B20: F1. Autenticacion / Roles | C20: AUTH-05 | D20: AUTH | E20: Tecnico/Dev | F20: redirect_uri no permitido | G20: - | H20: 1) Con dev, llamar a auth con redirect_uri de un dominio no listado | I20: HTTP 400: Keycloak rechaza (no esta en el allowlist del cliente) | J20: Alta | K20: Seguridad | L20: Pass | O20: redirect_uri no permitido -> 400 (10) | P20: Si | Q20: Pass | R20: Si
A21: 20 | B21: F1. Autenticacion / Roles | C21: AUTH-06 | D21: AUTH | E21: Manual-QA | F21: Sesion se mantiene (refresh de token) | G21: Sesion iniciada (P) | H21: 1) Dejar la app abierta ~5-10 min sin cerrar 2) Hacer una accion (abrir una consola) | I21: La app sigue funcionando sin pedir re-login (el token se refresco solo) | J21: Media | K21: Funcional | L21: Blocked | O21: refresh token UI (sesion) | P21: Si | Q21: Pass | R21: NO
A22: 21 | B22: F1. Autenticacion / Roles | C22: AUTH-07 | D22: AUTH | E22: Tecnico/Dev | F22: Sesion expirada real | G22: - | H22: 1) Con dev, invalidar/expirar el refresh-token o la sesion SSO 2) Hacer una accion | I22: La app detecta la sesion expirada y pide re-login | J22: Media | K22: Negativo | L22: Blocked | O22: invalidar sesion (dev) | P22: Si | Q22: Blocked | R22: Si
A23: 22 | B23: F1. Autenticacion / Roles | C23: AUTH-08 | D23: AUTH | E23: Tecnico/Dev | F23: Acceso sin token a un endpoint protegido | G23: - | H23: 1) Con curl/Postman, GET a /api/query/mt101-fragments/pay-conflicts/open sin cabecera Authorization | I23: HTTP 401 (no autorizado) | J23: Alta | K23: Seguridad | L23: Pass | O23: GET /api sin token -> 401 (08) | P23: Si | Q23: Pass | R23: Si
A24: 23 | B24: F1. Autenticacion / Roles | C24: AUTH-09 | D24: AUTH | E24: Manual-QA | F24: Rol payments-operator ve PAY conflicts | G24: Login como payments-operator (P); maker-checker OFF | H24: 1) Ir a Audit > PAY Conflicts 2) En un conflicto: Resolver | I24: Puede ver el inbox y (con maker-checker OFF) reconocer con motivo+ticket | J24: Alta | K24: Funcional | L24: Pass | O24: payments-operator: menu recortado + redirect desde /sources (UI 38) | P24: Si | Q24: Pass | R24: Si
A25: 24 | B25: F1. Autenticacion / Roles | C25: AUTH-10 | D25: AUTH | E25: Manual-QA | F25: Rol auditor es solo-lectura | G25: Login como auditor (P) | H25: 1) Ir a Audit > PAY Conflicts 2) Intentar reconocer/pagar | I25: Puede VER, pero las acciones que mueven dinero le dan error/estan bloqueadas (403) | J25: Alta | K25: Seguridad | L25: Pass | O25: auditor solo-lectura: VE el conflicto pero sin acciones de dinero (UI 38) | P25: Si | Q25: Pass | R25: Si
A26: 25 | B26: F1. Autenticacion / Roles | C26: AUTH-11 | D26: AUTH | E26: Manual-QA | F26: Rol pay-conflict-maker NO puede aprobar | G26: maker-checker ON; login como pay-maker (P); un PENDING existe | H26: 1) Ver el conflicto con la solicitud pendiente 2) Intentar Aprobar | I26: El boton Aprobar esta deshabilitado (te falta el rol checker); por API daria 403 | J26: Alta | K26: Seguridad | L26: Pass | O26: maker->approve 403 por rol (API 36); "por API daria 403" exacto | P26: No | R26: -
A27: 26 | B27: F1. Autenticacion / Roles | C27: AUTH-12 | D27: AUTH | E27: Manual-QA | F27: Rol pay-conflict-checker NO puede solicitar | G27: maker-checker ON; login como pay-checker (P) | H27: 1) En un conflicto, buscar 'Solicitar reconocimiento' | I27: No se te ofrece Solicitar (te falta el rol maker); por API daria 403 | J27: Alta | K27: Seguridad | L27: Pass | O27: checker->request 403 por rol (API 36) | P27: Si | Q27: Pass | R27: Si
A28: 27 | B28: F1. Autenticacion / Roles | C28: AUTH-13 | D28: AUTH | E28: Manual-QA | F28: Usuario sin rol maker/checker | G28: maker-checker ON; login como operator (sin roles dedicados) | H28: 1) Abrir el panel de un conflicto | I28: La UI avisa 'no tienes rol maker/checker' y no ofrece acciones | J28: Media | K28: Seguridad | L28: Pass | O28: admin sin rol maker/checker: "No tienes rol..." + sin botones (UI 37) | P28: Si | Q28: Pass | R28: Si
A29: 28 | B29: F1. Autenticacion / Roles | C29: AUTH-14 | D29: AUTH | E29: Manual-QA | F29: La URL de Keycloak es correcta | G29: Navegador; stack arriba | H29: 1) Iniciar login 2) Mirar la URL de la pantalla de Keycloak | I29: Es la URL publica esperada (dominio/IP con https), la misma con que entraste | J29: Media | K29: Funcional | L29: Blocked | O29: UI (pantalla Keycloak) | P29: Si | Q29: Pass | R29: NO
A30: 29 | B30: F2. Configuracion (catalogo) | C30: CSRC-01 | D30: CSRC | E30: Manual-QA | F30: Listar, buscar y filtrar fuentes | G30: Login como admin (P); menu Fuentes (/appih/#/sources) | H30: 1) Abrir Fuentes 2) Ver la lista (nombre, tipo, estado) 3) Escribir en Buscar un texto 4) Usar el filtro Tipo (SFTP / FTP / Amazon S3 / REST...) 5) Usar el filtro Estado (Activo / Inactivo) | I30: La lista se filtra por texto, por tipo y por estado; cada fila muestra nombre, tipo y si esta activa | J30: Media | K30: Funcional | L30: Pass | O30: GET source-definitions 200 (lista) | P30: No | R30: -
A31: 30 | B31: F2. Configuracion (catalogo) | C31: CSRC-02 | D31: CSRC | E31: Manual-QA | F31: Crear fuente SFTP (Probar + Guardar) | G31: Login admin (P); sftp-source arriba | H31: 1) Fuentes > Nueva fuente 2) Nombre = Fuente SFTP QA 3) Tipo = SFTP 4) Host = sftp-source ; Port = 22 ; Username = ihsource ; Password = ihsource ; Remote path = /upload/mt101-10k.csv (RUTA COMPLETA al archivo, no el directorio) 5) Media type = text/plain ; Strict host key checking = OFF ; Timeout (ms) = 10000 6) Click Probar (Test) 7) Click Guardar (Save) | I31: Probar devuelve conexion OK; al Guardar la fuente aparece en la lista como Activa. Nota (verificado en int): la fuente SFTP lee la RUTA COMPLETA del Remote path (sin fileNameTemplate en el form) | J31: Alta | K31: Funcional | L31: Pass | O31: POST source SFTP id=1 (20) | P31: Si | Q31: Pass | R31: Si
A32: 31 | B32: F2. Configuracion (catalogo) | C32: CSRC-03 | D32: CSRC | E32: Manual-QA | F32: Crear fuente Amazon S3 / MinIO | G32: Login admin (P); minio arriba (bucket ih-source-inbox) | H32: 1) Nueva fuente 2) Nombre = Fuente S3 QA ; Tipo = Amazon S3 3) Region = us-east-1 ; Bucket = ih-source-inbox ; Endpoint = http://minio:9000 4) Auth mode = access-key -> Access key ID = minioadmin ; Secret access key = minioadmin 5) Path-style access = ON ; Selection mode = all ; Media type = text/plain 6) Probar 7) Guardar | I32: Probar OK contra MinIO; se guarda como Activa. Nota (verificado en int): MinIO exige Path-style access = ON; y Auth mode = access-key es OBLIGATORIO (con Access key ID + Secret access key). Sin authMode:access-key el backend cae a la cadena de credenciales AWS por defecto y falla con 'Unable to load credentials' | J32: Alta | K32: Funcional | L32: Pass | O32: POST fuente S3 id=2 (26) | P32: Si | Q32: Pass | R32: Si
A33: 32 | B33: F2. Configuracion (catalogo) | C33: CSRC-04 | D33: CSRC | E33: Manual-QA | F33: Crear fuente FTP | G33: Login admin (P); ftp-source arriba | H33: 1) Nueva fuente 2) Nombre = Fuente FTP QA ; Tipo = FTP 3) Host = ftp-source ; Port = 21 ; Username = ihftp ; Password = ihftp ; Remote path = / 4) Passive mode = ON ; Timeout (ms) = 10000 ; Media type = text/plain 5) Probar 6) Guardar | I33: Probar OK; se guarda Activa | J33: Media | K33: Funcional | L33: Pass | O33: POST fuente FTP id=3 (26) | P33: Si | Q33: Pass | R33: Si
A34: 33 | B34: F2. Configuracion (catalogo) | C34: CSRC-05 | D34: CSRC | E34: Manual-QA | F34: Crear fuente REST | G34: Login admin (P); servicio echo arriba | H34: 1) Nueva fuente 2) Nombre = Fuente REST QA ; Tipo = REST 3) URL = http://echo ; Method = GET ; Auth type = No authentication 4) File name = echo-payload.json ; Timeout (s) = 10 ; Media type = application/json 5) Probar 6) Guardar | I34: Probar OK contra echo (HTTP 200); se guarda Activa | J34: Media | K34: Funcional | L34: Pass | O34: POST fuente REST id=4 (26) | P34: Si | Q34: Pass | R34: Si
A35: 34 | B35: F2. Configuracion (catalogo) | C35: CSRC-06 | D35: CSRC | E35: Manual-QA | F35: Editar una fuente existente | G35: Una fuente SFTP guardada (CSRC-02) | H35: 1) Abrir la fuente en la lista 2) Click Editar 3) Cambiar Remote path = /upload/qa 4) Guardar | I35: El cambio se guarda; al reabrir la fuente muestra el valor nuevo | J35: Media | K35: Funcional | L35: Pass | O35: PUT source (editar remotePath) 200 (24) | P35: No | R35: -
A36: 35 | B36: F2. Configuracion (catalogo) | C36: CSRC-07 | D36: CSRC | E36: Manual-QA | F36: Probar con credencial invalida (fail-loud) | G36: Login admin (P) | H36: 1) Nueva fuente SFTP con los datos de CSRC-02 pero Password = malo 2) Click Probar | I36: Probar FALLA con mensaje claro de error de conexion/autenticacion; no se cuelga y no da la fuente por buena | J36: Alta | K36: Negativo | L36: Pass | O36: test SFTP: buena OK; mala -> 500 fail-loud (32) | P36: Si | Q36: Pass | R36: Si
A37: 36 | B37: F2. Configuracion (catalogo) | C37: CSRC-08 | D37: CSRC | E37: Manual-QA | F37: Desactivar / Reactivar (baja logica; NO hay borrado) | G37: Una fuente Activa guardada | H37: 1) Abrir la fuente 2) Click Desactivar (toggle Activo) 3) En la lista, filtro Estado = Inactivo: confirmar que aparece 4) Reactivar | I37: La fuente pasa a Inactiva (deja de procesarse) y se puede reactivar. NO existe boton de borrado fisico: la baja es logica (se conserva para auditoria) | J37: Media | K37: Seguridad | L37: Pass | O37: PUT desactivar fuente S3 200 (27) | P37: No | R37: -
A38: 37 | B38: F2. Configuracion (catalogo) | C38: CSRC-09 | D38: CSRC | E38: Manual-QA | F38: Validacion de campos requeridos | G38: Login admin (P) | H38: 1) Nueva fuente 2) Dejar Nombre vacio y/o Host vacio 3) Intentar Guardar | I38: No deja guardar incompleto: el boton Guardar esta deshabilitado o marca el campo requerido | J38: Media | K38: Negativo | L38: Pass | O38: fix desplegado y verificado en vivo: boton Crear deshabilitado con Nombre vacio + backend 400 (requireName + ApiExceptionMapper). Commit 19203c63 (38) | P38: No | R38: -
A39: 38 | B39: F2. Configuracion (catalogo) | C39: CSRC-10 | D39: CSRC | E39: Manual-QA | F39: Cambiar de Tipo re-dibuja el formulario | G39: Login admin (P) | H39: 1) Nueva fuente 2) Tipo = SFTP (aparecen Host/Port/Username...) 3) Cambiar Tipo = Amazon S3 | I39: El formulario cambia a los campos de S3 (Bucket/Region/Endpoint/Auth mode) sin romperse | J39: Baja | K39: Funcional | L39: Pass | O39: cambiar Tipo redibuja el form (SFTP<->S3) sin romperse (UI 38) | P39: No | R39: -
A40: 39 | B40: F2. Configuracion (catalogo) | C40: CSRC-11 | D40: CSRC | E40: Tecnico/Dev | F40: Fuente File system (requiere ruta montada) | G40: Login admin (P) | H40: 1) Nueva fuente Tipo = File system 2) Path = /data/inbox ; Selection mode = all 3) Guardar / Probar | I40: En el stack int NO hay volumen de archivos montado en el contenedor de la app por defecto; para lectura real montar un volumen o usar SFTP/S3/FTP. Marcar N/A si no aplica en el ambiente | J40: Baja | K40: Funcional | L40: N/A | O40: File system: sin volumen montado en el app (int) | P40: Si | Q40: N/A | R40: Si
...

Sheet Preparacion
A1: PREPARACION - leer antes de ejecutar
A3: 1. Acceso
A4: URL | B4: Abrir en el navegador: https://<host>/appih (local de pruebas: https://192.168.0.15:8443/appih)
A5: Cert self-signed | B5: Sale un aviso de seguridad. En Firefox: Avanzado -> Aceptar el riesgo y continuar. En Chrome: escribir thisisunsafe en la pagina. (Una vez por origen.)
A7: 2. Usuarios de prueba | B7: usuario / contrasena -> para que sirve
A8: admin | B8: admin123 -> acceso completo (todo)
A9: operator | B9: operator123 -> operador de procesos
A10: auditor | B10: auditor123 -> SOLO LECTURA (no mueve dinero)
A11: payments-operator | B11: payments123 -> opera pagos; reconoce en modo single-actor
A12: pay-maker | B12: maker123 -> rol MAKER (solicita reconocer) [maker-checker]
A13: pay-checker | B13: checker123 -> rol CHECKER (aprueba) [maker-checker]
A15: 3. Navegacion | B15: La app usa el menu lateral. Seccion Audit:
A16: PAY Conflicts | B16: Audit > PAY Conflicts -> inbox de conflictos de pago (el corazon del maker-checker)
A17: Quarantine | B17: Audit > Quarantine -> filas invalidas para corregir
... A44: Regla | B44: No se puede correr F3 (E2E) sin F2 (configurar); ni F8 (aceptacion bancaria) sin haber pagado (F3/F4). La hoja Resumen tiene el conteo Por fase.
A46: 6. Notas
A47: maker-checker | B47: Los casos MC-05..23 y AUTH-11..13 requieren el modo maker-checker ACTIVADO (dev pone mt101.pay.conflict.acknowledge.maker-checker.enabled=true + reinicia el app).
A48: Estado | B48: En la hoja Casos, columna Estado: Pendiente / Pass / Fail / Blocked / N/A (menu desplegable). La hoja Resumen cuenta solo.

Sheet Datos-Formularios
A1: Pantalla | B1: Tipo | C1: Campo | D1: Valor a poner | E1: Nota
A2: Fuentes (/sources) | B2: Comun | C2: Nombre | D2: (libre) ej: Fuente SFTP QA | E2: Campo de la seccion Perfil
A3: Fuentes (/sources) | B3: Comun | C3: Tipo | D3: SFTP / FTP / Amazon S3 / REST / File system | E3: Selector; re-dibuja el formulario
A4: Fuentes (/sources) | B4: Comun | C4: Activo | D4: ON | E4: Toggle de la cabecera
A5: Fuentes (/sources) | B5: SFTP | C5: Host | D5: sftp-source
A6: Fuentes (/sources) | B6: SFTP | C6: Port | D6: 22
A7: Fuentes (/sources) | B7: SFTP | C7: Username | D7: ihsource
A8: Fuentes (/sources) | B8: SFTP | C8: Password | D8: ihsource
A9: Fuentes (/sources) | B9: SFTP | C9: Remote path | D9: /upload/mt101-10k.csv | E9: RUTA COMPLETA al archivo (verificado en int); el form SFTP no tiene fileNameTemplate
A10: Fuentes (/sources) | B10: SFTP | C10: Strict host key checking | D10: OFF | E10: Para pruebas int (sin known_hosts)
A11: Fuentes (/sources) | B11: SFTP | C11: Timeout (ms) | D11: 10000
A12: Fuentes (/sources) | B12: SFTP | C12: Media type | D12: text/plain
A13: Fuentes (/sources) | B13: Amazon S3 | C13: Region | D13: us-east-1
A14: Fuentes (/sources) | B14: Amazon S3 | C14: Bucket | D14: ih-source-inbox | E14: Bucket creado por minio-init
A15: Fuentes (/sources) | B15: Amazon S3 | C15: Endpoint | D15: http://minio:9000
A16: Fuentes (/sources) | B16: Amazon S3 | C16: Auth mode | D16: access-key | E16: OBLIGATORIO: muestra los campos de llaves. Sin access-key el backend cae a la cadena AWS por defecto y falla con "Unable to load credentials"
A17: Fuentes (/sources) | B17: Amazon S3 | C17: Access key ID | D17: minioadmin
A18: Fuentes (/sources) | B18: Amazon S3 | C18: Secret access key | D18: minioadmin
A19: Fuentes (/sources) | B19: Amazon S3 | C19: Path-style access | D19: ON | E19: OBLIGATORIO para MinIO
A20: Fuentes (/sources) | B20: Amazon S3 | C20: Selection mode | D20: all | E20: latestModified / single / all
A21: Fuentes (/sources) | B21: FTP | C21: Host | D21: ftp-source
A22: Fuentes (/sources) | B22: FTP | C22: Port | D22: 21
A23: Fuentes (/sources) | B23: FTP | C23: Username | D23: ihftp
A24: Fuentes (/sources) | B24: FTP | C24: Password | D24: ihftp
A25: Fuentes (/sources) | B25: FTP | C25: Remote path | D25: /
A26: Fuentes (/sources) | B26: FTP | C26: Passive mode | D26: ON
A27: Fuentes (/sources) | B27: REST | C27: URL | D27: http://echo | E27: Servicio echo del stack int
A28: Fuentes (/sources) | B28: REST | C28: Method | D28: GET
A29: Fuentes (/sources) | B29: REST | C29: Auth type | D29: No authentication | E29: None / Basic / Bearer
A30: Fuentes (/sources) | B30: REST | C30: File name | D30: echo-payload.json
A31: Fuentes (/sources) | B31: REST | C31: Timeout (s) | D31: 10
A32: Fuentes (/sources) | B32: File system | C32: Path | D32: /data/inbox | E32: Requiere volumen montado (int no lo trae)
A33: Conexiones (/connections) | B33: Comun | C33: Nombre | D33: (libre) ej: Conexion Postgres QA
A34: Conexiones (/connections) | B34: Comun | C34: Motor (Tipo) | D34: PostgreSQL | E34: PostgreSQL/Oracle/SQL Server/MySQL/MongoDB
A35: Conexiones (/connections) | B35: JDBC | C35: JDBC URL | D35: jdbc:postgresql://postgres:5432/integration_hub
A36: Conexiones (/connections) | B36: JDBC | C36: Username | D36: postgres
A37: Conexiones (/connections) | B37: JDBC | C37: Password | D37: admin
A38: Conexiones (/connections) | B38: JDBC | C38: Min size | D38: 1
A39: Conexiones (/connections) | B39: JDBC | C39: Max size | D39: 10
A40: Conexiones (/connections) | B40: JDBC | C40: Acquisition timeout (s) | D40: 5
...

Sheet Flujo-E2E
A1: FLUJO E2E MT101 (modulo E2E)
A3: Orden | B3: Configurar catalogo (Fase A) -> dejar el archivo en docker (Fase B) -> ejecutar y verificar por etapa (Fase C) -> reprocesos (Fase D).
A5: 0) Archivos entregados | B5: En qa/fase-6-qa/datos-prueba/: mt101-10k.csv (10.000 filas, VOLUMEN) ; mt101-10k.xlsx ; mt101-10k.txt (ancho fijo) ; mt101-6.csv (humo). Ver LEEME-datos.md para la config de reader por formato. El QA NO tiene que generar nada.
A7: 1) Esquema / muestra (6 filas) | B7: Esquema de columnas (el mismo en los 4 archivos). En el humo de 6 filas el caracter ~ en concepto lo limpia MT101_REPAIR (demuestra la reparacion SWIFT-X):
A8: cabecera | B8: dni,nombre,cuenta,moneda,monto,bic,concepto,cargos
A9: fila 1 | B9: 10000001,BENEFICIARIO 1,001000000001,PEN,101.50,BCPLPEPLXXX,PAGO ~ 1,SHA
A10: fila 2 | B10: 10000002,BENEFICIARIO 2,001000000002,PEN,102.50,BCPLPEPLXXX,PAGO ~ 2,SHA
A11: fila 3 | B11: 10000003,BENEFICIARIO 3,001000000003,PEN,103.50,BCPLPEPLXXX,PAGO ~ 3,SHA
A12: fila 4 | B12: 10000004,BENEFICIARIO 4,001000000004,PEN,104.50,BCPLPEPLXXX,PAGO ~ 4,SHA
A13: fila 5 | B13: 10000005,BENEFICIARIO 5,001000000005,PEN,105.50,BCPLPEPLXXX,PAGO ~ 5,SHA
A14: fila 6 | B14: 10000006,BENEFICIARIO 6,001000000006,PEN,106.50,BCPLPEPLXXX,PAGO ~ 6,SHA
A16: 2) Reader CSV (E2E-02) | B16: 8 columnas por posicion: dni(1) nombre(2) cuenta(3) moneda(4) monto(5,NUMBER) bic(6) concepto(7) cargos(8). Delimiter=, Encoding=UTF-8 Data starts at row=2.
A18: 3) Dejar el archivo (E2E-05) | B18: Puertos SFTP/FTP/MinIO NO expuestos al host -> copiar dentro del contenedor:
... A28: 7) Reprocesos | B28: E2E-15 cuarentena+corregir ; E2E-16 reingreso idempotente (0 pagos nuevos) ; E2E-17 rechazo->run correctivo ; E2E-18 no-enviado->re-solicitar ; E2E-19 maker-checker

Sheet Resumen
A1: Resumen de ejecucion QA
A3: Total de casos | B3: =COUNTA(Casos!C2:C237) -> 236
A5: Estado | B5: Cantidad | D5: Ejecutor | E5: Cantidad
A6: Pendiente | B6: =COUNTIF(Casos!L2:L237,"Pendiente") -> 0 | D6: Manual-QA | E6: =COUNTIF(Casos!E2:E237,"Manual-QA") -> 111
A7: Pass | B7: =COUNTIF(Casos!L2:L237,"Pass") -> 142 | D7: Tecnico/Dev | E7: =COUNTIF(Casos!E2:E237,"Tecnico/Dev") -> 93
A8: Fail | B8: =COUNTIF(Casos!L2:L237,"Fail") -> 0 | D8: Automatizado-IT | E8: =COUNTIF(Casos!E2:E237,"Automatizado-IT") -> 32
A9: Blocked | B9: =COUNTIF(Casos!L2:L237,"Blocked") -> 90
A10: N/A | B10: =COUNTIF(Casos!L2:L237,"N/A") -> 4
A12: Por fase (orden de ejecucion)
A13: Fase | B13: Casos | C13: Pass | D13: Fail
A14: F0. Infra / Deploy / Acceso | B14: =COUNTIF(Casos!B2:B237,"F0. Infra / Deploy / Acceso") -> 14 | C14: =COUNTIFS(Casos!B2:B237,"F0. Infra / Deploy / Acceso",Casos!L2:L237,"Pass") -> 10 | D14: =COUNTIFS(Casos!B2:B237,"F0. Infra / Deploy / Acceso",Casos!L2:L237,"Fail") -> 0
A15: F1. Autenticacion / Roles | B15: =COUNTIF(Casos!B2:B237,"F1. Autenticacion / Roles") -> 14 | C15: =COUNTIFS(Casos!B2:B237,"F1. Autenticacion / Roles",Casos!L2:L237,"Pass") -> 8 | D15: =COUNTIFS(Casos!B2:B237,"F1. Autenticacion / Roles",Casos!L2:L237,"Fail") -> 0
A16: F2. Configuracion (catalogo) | B16: =COUNTIF(Casos!B2:B237,"F2. Configuracion (catalogo)") -> 33 | C16: =COUNTIFS(Casos!B2:B237,"F2. Configuracion (catalogo)",Casos!L2:L237,"Pass") -> 31 | D16: =COUNTIFS(Casos!B2:B237,"F2. Configuracion (catalogo)",Casos!L2:L237,"Fail") -> 0
A17: F3. Flujo E2E (money-path) | B17: =COUNTIF(Casos!B2:B237,"F3. Flujo E2E (money-path)") -> 23 | C17: =COUNTIFS(Casos!B2:B237,"F3. Flujo E2E (money-path)",Casos!L2:L237,"Pass") -> 16 | D17: =COUNTIFS(Casos!B2:B237,"F3. Flujo E2E (money-path)",Casos!L2:L237,"Fail") -> 0
A18: F4. Profundizacion por etapa | B18: =COUNTIF(Casos!B2:B237,"F4. Profundizacion por etapa") -> 68 | C18: =COUNTIFS(Casos!B2:B237,"F4. Profundizacion por etapa",Casos!L2:L237,"Pass") -> 44 | D18: =COUNTIFS(Casos!B2:B237,"F4. Profundizacion por etapa",Casos!L2:L237,"Fail") -> 0
A19: F5. Maker-checker / Consolas | B19: =COUNTIF(Casos!B2:B237,"F5. Maker-checker / Consolas") -> 36 | C19: =COUNTIFS(Casos!B2:B237,"F5. Maker-checker / Consolas",Casos!L2:L237,"Pass") -> 17 | D19: =COUNTIFS(Casos!B2:B237,"F5. Maker-checker / Consolas",Casos!L2:L237,"Fail") -> 0
A20: F6. Plataforma / Auditoria | B20: =COUNTIF(Casos!B2:B237,"F6. Plataforma / Auditoria") -> 14 | C20: =COUNTIFS(Casos!B2:B237,"F6. Plataforma / Auditoria",Casos!L2:L237,"Pass") -> 3 | D20: =COUNTIFS(Casos!B2:B237,"F6. Plataforma / Auditoria",Casos!L2:L237,"Fail") -> 0
A21: F7. No funcionales | B21: =COUNTIF(Casos!B2:B237,"F7. No funcionales") -> 12 | C21: =COUNTIFS(Casos!B2:B237,"F7. No funcionales",Casos!L2:L237,"Pass") -> 7 | D21: =COUNTIFS(Casos!B2:B237,"F7. No funcionales",Casos!L2:L237,"Fail") -> 0
A22: F8. Aceptacion bancaria (homologacion) | B22: =COUNTIF(Casos!B2:B237,"F8. Aceptacion bancaria (homologacion)") -> 22 | C22: =COUNTIFS(Casos!B2:B237,"F8. Aceptacion bancaria (homologacion)",Casos!L2:L237,"Pass") -> 6 | D22: =COUNTIFS(Casos!B2:B237,"F8. Aceptacion bancaria (homologacion)",Casos!L2:L237,"Fail") -> 0
A24: Por modulo
A25: Modulo | B25: Casos | C25: Pass | D25: Fail | E25: Descripcion
A26: INFRA | B26: =COUNTIF(Casos!D2:D237,"INFRA") -> 14 | C26: =COUNTIFS(Casos!D2:D237,"INFRA",Casos!L2:L237,"Pass") -> 10 | D26: =COUNTIFS(Casos!D2:D237,"INFRA",Casos!L2:L237,"Fail") -> 0 | E26: Deploy / Infraestructura / Acceso (nginx, TLS, /appih)
A27: AUTH | B27: =COUNTIF(Casos!D2:D237,"AUTH") -> 14 | C27: =COUNTIFS(Casos!D2:D237,"AUTH",Casos!L2:L237,"Pass") -> 8 | D27: =COUNTIFS(Casos!D2:D237,"AUTH",Casos!L2:L237,"Fail") -> 0 | E27: Autenticacion / OIDC / Roles (Keycloak)
A28: CSRC | B28: =COUNTIF(Casos!D2:D237,"CSRC") -> 12 | C28: =COUNTIFS(Casos!D2:D237,"CSRC",Casos!L2:L237,"Pass") -> 11 | D28: =COUNTIFS(Casos!D2:D237,"CSRC",Casos!L2:L237,"Fail") -> 0 | E28: Config CRUD: Fuentes (/appih/#/sources) con valores por campo
A29: CCON | B29: =COUNTIF(Casos!D2:D237,"CCON") -> 6 | C29: =COUNTIFS(Casos!D2:D237,"CCON",Casos!L2:L237,"Pass") -> 5 | D29: =COUNTIFS(Casos!D2:D237,"CCON",Casos!L2:L237,"Fail") -> 0 | E29: Config CRUD: Conexiones JDBC (/appih/#/connections)
A30: CRDR | B30: =COUNTIF(Casos!D2:D237,"CRDR") -> 7 | C30: =COUNTIFS(Casos!D2:D237,"CRDR",Casos!L2:L237,"Pass") -> 7 | D30: =COUNTIFS(Casos!D2:D237,"CRDR",Casos!L2:L237,"Fail") -> 0 | E30: Config CRUD: Readers (/appih/#/readers)
A31: CPRO | B31: =COUNTIF(Casos!D2:D237,"CPRO") -> 8 | C31: =COUNTIFS(Casos!D2:D237,"CPRO",Casos!L2:L237,"Pass") -> 8 | D31: =COUNTIFS(Casos!D2:D237,"CPRO",Casos!L2:L237,"Fail") -> 0 | E31: Config CRUD: Procesos + Ejecuciones (/appih/#/processes)
A32: E2E | B32: =COUNTIF(Casos!D2:D237,"E2E") -> 23 | C32: =COUNTIFS(Casos!D2:D237,"E2E",Casos!L2:L237,"Pass") -> 16 | D32: =COUNTIFS(Casos!D2:D237,"E2E",Casos!L2:L237,"Fail") -> 0 | E32: Flujo E2E: configurar -> dejar archivo -> ejecutar -> verificar -> reprocesar
A33: SRC | B33: =COUNTIF(Casos!D2:D237,"SRC") -> 11 | C33: =COUNTIFS(Casos!D2:D237,"SRC",Casos!L2:L237,"Pass") -> 7 | D33: =COUNTIFS(Casos!D2:D237,"SRC",Casos!L2:L237,"Fail") -> 0 | E33: Fuentes (SFTP / FTP / S3-MinIO)
A34: MP | B34: =COUNTIF(Casos!D2:D237,"MP") -> 17 | C34: =COUNTIFS(Casos!D2:D237,"MP",Casos!L2:L237,"Pass") -> 11 | D34: =COUNTIFS(Casos!D2:D237,"MP",Casos!L2:L237,"Fail") -> 0 | E34: MT101 Money-path (lectura -> construccion -> validacion -> archivo)
A35: PAY | B35: =COUNTIF(Casos!D2:D237,"PAY") -> 21 | C35: =COUNTIFS(Casos!D2:D237,"PAY",Casos!L2:L237,"Pass") -> 15 | D35: =COUNTIFS(Casos!D2:D237,"PAY",Casos!L2:L237,"Fail") -> 0 | E35: PAY / Anti-doble-pago (money-safety, dos nodos)
A36: CORR | B36: =COUNTIF(Casos!D2:D237,"CORR") -> 10 | C36: =COUNTIFS(Casos!D2:D237,"CORR",Casos!L2:L237,"Pass") -> 8 | D36: =COUNTIFS(Casos!D2:D237,"CORR",Casos!L2:L237,"Fail") -> 0 | E36: PAY Correctivo (rechazo, run hijo, parcial)
A37: STAT | B37: =COUNTIF(Casos!D2:D237,"STAT") -> 9 | C37: =COUNTIFS(Casos!D2:D237,"STAT",Casos!L2:L237,"Pass") -> 3 | D37: =COUNTIFS(Casos!D2:D237,"STAT",Casos!L2:L237,"Fail") -> 0 | E37: STATUS / RECONCILE / Confirmaciones del banco
A38: MC | B38: =COUNTIF(Casos!D2:D237,"MC") -> 24 | C38: =COUNTIFS(Casos!D2:D237,"MC",Casos!L2:L237,"Pass") -> 13 | D38: =COUNTIFS(Casos!D2:D237,"MC",Casos!L2:L237,"Fail") -> 0 | E38: Maker-checker / PAY_CONFLICT (tanda-8/9)
A39: UI | B39: =COUNTIF(Casos!D2:D237,"UI") -> 12 | C39: =COUNTIFS(Casos!D2:D237,"UI",Casos!L2:L237,"Pass") -> 4 | D39: =COUNTIFS(Casos!D2:D237,"UI",Casos!L2:L237,"Fail") -> 0 | E39: Consolas de UI (PAY conflicts, quarantine, lineage)
A40: PLG | B40: =COUNTIF(Casos!D2:D237,"PLG") -> 8 | C40: =COUNTIFS(Casos!D2:D237,"PLG",Casos!L2:L237,"Pass") -> 1 | D40: =COUNTIFS(Casos!D2:D237,"PLG",Casos!L2:L237,"Fail") -> 0 | E40: Plugins out-of-process (gRPC + widget)
A41: AUD | B41: =COUNTIF(Casos!D2:D237,"AUD") -> 6 | C41: =COUNTIFS(Casos!D2:D237,"AUD",Casos!L2:L237,"Pass") -> 2 | D41: =COUNTIFS(Casos!D2:D237,"AUD",Casos!L2:L237,"Fail") -> 0 | E41: Auditoria asincrona (Kafka -> store frio)
A42: NF | B42: =COUNTIF(Casos!D2:D237,"NF") -> 12 | C42: =COUNTIFS(Casos!D2:D237,"NF",Casos!L2:L237,"Pass") -> 7 | D42: =COUNTIFS(Casos!D2:D237,"NF",Casos!L2:L237,"Fail") -> 0 | E42: No funcionales (rendimiento, resiliencia, seguridad)
A43: BANK | B43: =COUNTIF(Casos!D2:D237,"BANK") -> 22 | C43: =COUNTIFS(Casos!D2:D237,"BANK",Casos!L2:L237,"Pass") -> 6 | D43: =COUNTIFS(Casos!D2:D237,"BANK",Casos!L2:L237,"Fail") -> 0 | E43: Controles criticos bancarios / homologacion (vista consolidada)

Sheet Aprobacion
A1: CHECKLIST DE APROBACION / HOMOLOGACION — Money-path MT101
A2: Cada gate se cierra cuando sus casos de referencia estan en Pass. Marcar Resultado y adjuntar evidencia. Al final, firmas.
A3: ID | B3: Criterio de aceptacion (gate) | C3: Casos de referencia | D3: Resultado | E3: Observaciones / Evidencia
A4: G-01 | B4: Cero doble pago (anti-doble-pago) verificado en el banco | C4: BANK-01, PAY-05..12, E2E-16/18, NF-03 | D4: Pendiente
A5: G-02 | B5: Ningun pago queda huerfano (todos en estado final) | C5: BANK-02 | D5: Pendiente
A6: G-03 | B6: Toda contradiccion -> PAY_CONFLICT (nunca silenciosa) | C6: BANK-03, STAT-08, E2E-17 | D6: Pendiente
A7: G-04 | B7: Segregacion de funciones / maker-checker (four-eyes) | C7: BANK-04, MC-06..18, E2E-19 | D7: Pendiente
A8: G-05 | B8: Auditoria inmutable / no repudio | C8: BANK-05, AUD-02, MC-22 | D8: Pendiente
A9: G-06 | B9: Trazabilidad E2E de un pago (:20:) | C9: BANK-06, E2E-14 | D9: Pendiente
A10: G-07 | B10: Cuadre fin de dia (enviado == confirmado) | C10: BANK-07, STAT-06, E2E-13 | D10: Pendiente
A11: G-08 | B11: Idempotencia (reingreso no duplica) | C11: BANK-08, E2E-16 | D11: Pendiente
A12: G-09 | B12: Validacion MT101 / cuarentena (nada mal formado al banco) | C12: BANK-10, MP-05..08, E2E-15 | D12: Pendiente
A13: G-10 | B13: Precision de monto/moneda | C13: BANK-11 | D13: Pendiente
A14: G-11 | B14: Controles bancarios ACTIVOS en prod | C14: BANK-16, NF-06 | D14: Pendiente
A15: G-12 | B15: RBAC / minimo privilegio | C15: BANK-20, AUTH-09..13 | D15: Pendiente
... A19: G-16 | B19: CRUD de catalogo (Fuentes/Conexiones/Readers/Procesos) | C19: CSRC, CCON, CRDR, CPRO | D19: Pendiente
A21: DECISION DE HOMOLOGACION Y FIRMAS
B22: Rol | C22: Nombre y cargo | D22: Decision | E22: Firma y fecha
B23: Lider QA
B24: Lider Tecnico / Dev
B25: Dueno de negocio / Producto
B26: Seguridad / Riesgos
B27: Representante del banco (opcional)
